Traceback (most recent call last):
  File "/hpc/home/rl330/coganlab/rl330/GlobalLocal/src/analysis/pac/theta_connect.py", line 174, in <module>
    compute_and_plot_connectivity(
  File "/hpc/home/rl330/coganlab/rl330/GlobalLocal/src/analysis/pac/theta_connect.py", line 124, in compute_and_plot_connectivity
    plt.plot(times, conn_time[idx], label=label)
  File "/hpc/group/coganlab/rl330/miniconda3/envs/ieeg/lib/python3.11/site-packages/matplotlib/pyplot.py", line 3838, in plot
    return gca().plot(
           ^^^^^^^^^^^
  File "/hpc/group/coganlab/rl330/miniconda3/envs/ieeg/lib/python3.11/site-packages/matplotlib/axes/_axes.py", line 1777, in plot
    lines = [*self._get_lines(self, *args, data=data, **kwargs)]
            ^^^^^^^^^^^^^^^^^^^^^^^^^^^^^^^^^^^^^^^^^^^^^^^^^^^^
  File "/hpc/group/coganlab/rl330/miniconda3/envs/ieeg/lib/python3.11/site-packages/matplotlib/axes/_base.py", line 297, in __call__
    yield from self._plot_args(
               ^^^^^^^^^^^^^^^^
  File "/hpc/group/coganlab/rl330/miniconda3/envs/ieeg/lib/python3.11/site-packages/matplotlib/axes/_base.py", line 494, in _plot_args
    raise ValueError(f"x and y must have same first dimension, but "
ValueError: x and y must have same first dimension, but have shapes (449,) and (2,)
